Workbook
Name CATEGORIAS: 'UNIVERSO PRODUCTOS'!$A$1:$H$961
Name central: #REF!
Name samu: #REF!
Name samuel: #REF!

Sheet Ingredientes
A1: ID Ingrediente | B1: Nombre Ingrediente | C1: Cantidad | D1: Costo Total

Sheet UNIVERSO PRODUCTOS
A1: ID | B1: Nombre | C1: Precio | D1: Unidad de medida | E1: Conversiones | F1: ID externo | G1: ID Categoria | H1: Nombre Categoria | I1: ID Categoria Externo | J1: ID Bodegas | K1: Nombre Bodegas | L1: Impuestos
A2: ti-ing-b69bd6ae-ccae-4801-af83-bece901d304f | B2: Aceite oliva extra virgen 5 lts | C2: 4646.2 | D2: LT | G2: ti-incat-dbb4ab5d-d383-44df-bb1b-2819d297b20d | H2: Abarrotes | J2: ti-str-e3696e4b-7915-4d18-83e7-077d2c42d9bc,ti-str-bbb1d66c-36dd-47af-85d8-583c26959146,ti-str-36f261ca-0b74-4d79-8a50-81324d9ac308 | K2: Principal,Stock Cocina,Stock Panaderia | L2: iva_19
A3: ti-ing-5a1041f6-5fed-4ae0-8d00-dee7d47968a3 | B3: Aceite vegetal 900 ml | C3: 1540.6 | D3: UN | G3: ti-incat-dbb4ab5d-d383-44df-bb1b-2819d297b20d | H3: Abarrotes | J3: ti-str-e3696e4b-7915-4d18-83e7-077d2c42d9bc,ti-str-e0754139-882f-4237-83fa-744442ed825f,ti-str-bbb1d66c-36dd-47af-85d8-583c26959146,ti-str-36f261ca-0b74-4d79-8a50-81324d9ac308 | K3: Principal,Stock Pasteleria,Stock Cocina,Stock Panaderia | L3: iva_19
A4: ti-ing-0ab486df-7d4d-4782-82bb-c30b4209e5fb | B4: Aceituna Morada kg | C4: 7130 | D4: KG | G4: ti-incat-dbb4ab5d-d383-44df-bb1b-2819d297b20d | H4: Abarrotes | J4: ti-str-bbb1d66c-36dd-47af-85d8-583c26959146 | K4: Stock Cocina | L4: iva_19
A5: ti-ing-581e5046-d41b-44fd-981a-fa5ec2c4d4ba | B5: Ajinomoto | C5: 3354 | D5: kg | G5: ti-incat-dbb4ab5d-d383-44df-bb1b-2819d297b20d | H5: Abarrotes | J5: ti-str-e3696e4b-7915-4d18-83e7-077d2c42d9bc,ti-str-bbb1d66c-36dd-47af-85d8-583c26959146 | K5: Principal,Stock Cocina | L5: iva_19
A6: ti-ing-65292276-c9a9-4569-b8ff-19a5a3fea424 | B6: Anis kg | C6: 13854 | D6: Kg | G6: ti-incat-dbb4ab5d-d383-44df-bb1b-2819d297b20d | H6: Abarrotes | J6: ti-str-e3696e4b-7915-4d18-83e7-077d2c42d9bc,ti-str-36f261ca-0b74-4d79-8a50-81324d9ac308 | K6: Principal,Stock Panaderia | L6: iva_19
A7: ti-ing-bfd5d10e-d265-4e6e-b05a-79c836269380 | B7: Arroz (colacion) | C7: 905 | D7: KG | G7: ti-incat-dbb4ab5d-d383-44df-bb1b-2819d297b20d | H7: Abarrotes | J7: ti-str-e3696e4b-7915-4d18-83e7-077d2c42d9bc,ti-str-bbb1d66c-36dd-47af-85d8-583c26959146 | K7: Principal,Stock Cocina | L7: iva_19
A8: ti-ing-5c316419-1759-4d90-bb2e-e9025a87d122 | B8: Atun Coliseo Al Agua | C8: 879 | D8: UN | G8: ti-incat-dbb4ab5d-d383-44df-bb1b-2819d297b20d | H8: Abarrotes | J8: ti-str-e3696e4b-7915-4d18-83e7-077d2c42d9bc,ti-str-bbb1d66c-36dd-47af-85d8-583c26959146 | K8: Principal,Stock Cocina | L8: iva_19
A9: ti-ing-363a5ec1-8d6b-4612-be6a-7a19b61ab7e2 | B9: Atun Dorasol Al Agua | C9: 879 | D9: UN | G9: ti-incat-dbb4ab5d-d383-44df-bb1b-2819d297b20d | H9: Abarrotes | J9: ti-str-e3696e4b-7915-4d18-83e7-077d2c42d9bc,ti-str-bbb1d66c-36dd-47af-85d8-583c26959146 | K9: Principal,Stock Cocina | L9: iva_19
A10: ti-ing-c1414efc-1614-40c6-a7e8-2f6efb3e0401 | B10: Avena | C10: 1050 | D10: KG | G10: ti-incat-dbb4ab5d-d383-44df-bb1b-2819d297b20d | H10: Abarrotes | J10: ti-str-e3696e4b-7915-4d18-83e7-077d2c42d9bc,ti-str-36f261ca-0b74-4d79-8a50-81324d9ac308 | K10: Principal,Stock Panaderia | L10: iva_19
A11: ti-ing-531d1d9b-814d-49bc-9bbf-06be4ae2e6d5 | B11: Azucar blanca | C11: 939.9985 | D11: KG | G11: ti-incat-dbb4ab5d-d383-44df-bb1b-2819d297b20d | H11: Abarrotes | J11: ti-str-e3696e4b-7915-4d18-83e7-077d2c42d9bc,ti-str-e0754139-882f-4237-83fa-744442ed825f,ti-str-bbb1d66c-36dd-47af-85d8-583c26959146,ti-str-36f261ca-0b74-4d79-8a50-81324d9ac308,ti-str-eafdd243-ca10-4e67-89d4-50a191eb8e12 | K11: Principal,Stock Pasteleria,Stock Cocina,Stock Panaderia,Stock Servicio | L11: iva_19
B12: Azúcar blanca por kilo | C12: 930 | D12: KG | G12: ti-incat-dbb4ab5d-d383-44df-bb1b-2819d297b20d | H12: Abarrotes | K12: Principal,Stock Cocina | L12: iva_19
A13: ti-ing-c4486ce7-85c4-49c5-ac82-4d98b0798d01 | B13: Azucar rubia | C13: 1047 | D13: KG | G13: ti-incat-dbb4ab5d-d383-44df-bb1b-2819d297b20d | H13: Abarrotes | J13: ti-str-e3696e4b-7915-4d18-83e7-077d2c42d9bc,ti-str-e0754139-882f-4237-83fa-744442ed825f,ti-str-bbb1d66c-36dd-47af-85d8-583c26959146,ti-str-36f261ca-0b74-4d79-8a50-81324d9ac308,ti-str-eafdd243-ca10-4e67-89d4-50a191eb8e12 | K13: Principal,Stock Pasteleria,Stock Cocina,Stock Panaderia,Stock Servicio | L13: iva_19
A14: ti-ing-63a7f9f9-77ff-45f4-9e3f-3feff0b73432 | B14: Café tarro grande (desayuno) | C14: 12032 | D14: UN | G14: ti-incat-dbb4ab5d-d383-44df-bb1b-2819d297b20d | H14: Abarrotes | J14: ti-str-e3696e4b-7915-4d18-83e7-077d2c42d9bc,ti-str-e0754139-882f-4237-83fa-744442ed825f,ti-str-bbb1d66c-36dd-47af-85d8-583c26959146,ti-str-36f261ca-0b74-4d79-8a50-81324d9ac308,ti-str-eafdd243-ca10-4e67-89d4-50a191eb8e12 | K14: Principal,Stock Pasteleria,Stock Cocina,Stock Panaderia,Stock Servicio | L14: iva_19
A15: ti-ing-f57e1d6d-2d59-440c-a741-794a5d5d1359 | B15: Chia kg | C15: 4152 | D15: UN | G15: ti-incat-dbb4ab5d-d383-44df-bb1b-2819d297b20d | H15: Abarrotes | J15: ti-str-e3696e4b-7915-4d18-83e7-077d2c42d9bc,ti-str-36f261ca-0b74-4d79-8a50-81324d9ac308 | K15: Principal,Stock Panaderia | L15: iva_19
A16: ti-ing-b908bdf8-4d68-4e4a-bca8-67edb76d6236 | B16: Chips Chocolate Negro kg | C16: 6977.75 | D16: KG | G16: ti-incat-dbb4ab5d-d383-44df-bb1b-2819d297b20d | H16: Abarrotes | J16: ti-str-e3696e4b-7915-4d18-83e7-077d2c42d9bc,ti-str-e0754139-882f-4237-83fa-744442ed825f,ti-str-36f261ca-0b74-4d79-8a50-81324d9ac308 | K16: Principal,Stock Pasteleria,Stock Panaderia | L16: iva_19
A17: ti-ing-89800579-a778-4a4e-8895-e0cc7ed6a986 | B17: Coco Laminado | C17: 8474 | D17: KG | G17: ti-incat-dbb4ab5d-d383-44df-bb1b-2819d297b20d | H17: Abarrotes | J17: ti-str-e3696e4b-7915-4d18-83e7-077d2c42d9bc,ti-str-e0754139-882f-4237-83fa-744442ed825f,ti-str-36f261ca-0b74-4d79-8a50-81324d9ac308 | K17: Principal,Stock Pasteleria,Stock Panaderia | L17: iva_19
A18: ti-ing-a396335b-a1d5-46a1-874a-de8bd1a3a0de | B18: Coco Rallado | C18: 4188 | D18: KG | G18: ti-incat-dbb4ab5d-d383-44df-bb1b-2819d297b20d | H18: Abarrotes | J18: ti-str-e3696e4b-7915-4d18-83e7-077d2c42d9bc,ti-str-36f261ca-0b74-4d79-8a50-81324d9ac308,ti-str-e0754139-882f-4237-83fa-744442ed825f | K18: Principal,Stock Panaderia,Stock Pasteleria | L18: iva_19
A19: ti-ing-280562df-e2c6-469c-bfaf-8f7361fb5c74 | B19: COMINO | C19: 5250 | D19: KG | G19: ti-incat-dbb4ab5d-d383-44df-bb1b-2819d297b20d | H19: Abarrotes | J19: ti-str-e3696e4b-7915-4d18-83e7-077d2c42d9bc,ti-str-bbb1d66c-36dd-47af-85d8-583c26959146 | K19: Principal,Stock Cocina | L19: iva_19
A20: ti-ing-55e22a4e-70ba-4bfe-9ef6-78d09a6c71b6 | B20: Curcuma | C20: 5437 | D20: KG | G20: ti-incat-dbb4ab5d-d383-44df-bb1b-2819d297b20d | H20: Abarrotes | J20: ti-str-e3696e4b-7915-4d18-83e7-077d2c42d9bc,ti-str-bbb1d66c-36dd-47af-85d8-583c26959146 | K20: Principal,Stock Cocina | L20: iva_19
A21: ti-ing-064cb0f3-6635-4de8-915c-d57502a19286 | B21: Esencia vainilla | C21: 1000 | D21: LT | G21: ti-incat-dbb4ab5d-d383-44df-bb1b-2819d297b20d | H21: Abarrotes | J21: ti-str-e3696e4b-7915-4d18-83e7-077d2c42d9bc,ti-str-e0754139-882f-4237-83fa-744442ed825f,ti-str-36f261ca-0b74-4d79-8a50-81324d9ac308 | K21: Principal,Stock Pasteleria,Stock Panaderia | L21: iva_19
A22: ti-ing-2fbc1c56-3286-4d64-8ddd-b547296361a3 | B22: Espaguetti | C22: 407 | D22: UN | G22: ti-incat-dbb4ab5d-d383-44df-bb1b-2819d297b20d | H22: Abarrotes | J22: ti-str-e3696e4b-7915-4d18-83e7-077d2c42d9bc,ti-str-bbb1d66c-36dd-47af-85d8-583c26959146 | K22: Principal,Stock Cocina | L22: iva_19
A23: ti-ing-446530ff-42dc-41f9-9208-1b6c8dded86f | B23: Espirales | C23: 399 | D23: UN | G23: ti-incat-dbb4ab5d-d383-44df-bb1b-2819d297b20d | H23: Abarrotes | J23: ti-str-e3696e4b-7915-4d18-83e7-077d2c42d9bc,ti-str-bbb1d66c-36dd-47af-85d8-583c26959146 | K23: Principal,Stock Cocina | L23: iva_19
A24: ti-ing-150d078f-94cc-4527-a524-b16516d0adfa | B24: Fruta Confitada | C24: 3500 | D24: KG | G24: ti-incat-dbb4ab5d-d383-44df-bb1b-2819d297b20d | H24: Abarrotes | J24: ti-str-e3696e4b-7915-4d18-83e7-077d2c42d9bc,ti-str-36f261ca-0b74-4d79-8a50-81324d9ac308 | K24: Principal,Stock Panaderia | L24: iva_19
... A27: ti-ing-af062f27-295c-456a-9ce5-77fbb725f339 | B27: Helado Chocolate | C27: 2360.6 | D27: LT | G27: ti-incat-dbb4ab5d-d383-44df-bb1b-2819d297b20d | H27: Abarrotes | J27: ti-str-eafdd243-ca10-4e67-89d4-50a191eb8e12,ti-str-e3696e4b-7915-4d18-83e7-077d2c42d9bc | K27: Stock Servicio,Principal | L27: iva_19
B28: Helado frutilla | C28: 3469 | D28: LT | G28: ti-incat-dbb4ab5d-d383-44df-bb1b-2819d297b20d | H28: Abarrotes | J28: ti-str-eafdd243-ca10-4e67-89d4-50a191eb8e12,ti-str-e3696e4b-7915-4d18-83e7-077d2c42d9bc | K28: Stock Servicio,Principal | L28: iva_19
A29: ti-ing-12dbd538-5012-4d25-8c02-7d0b4f3fdf45 | B29: Helado Vainilla | C29: 2979 | D29: LT | G29: ti-incat-dbb4ab5d-d383-44df-bb1b-2819d297b20d | H29: Abarrotes | J29: ti-str-eafdd243-ca10-4e67-89d4-50a191eb8e12,ti-str-e3696e4b-7915-4d18-83e7-077d2c42d9bc | K29: Stock Servicio,Principal | L29: iva_19
A30: ti-ing-e6ff2cd2-0729-44b9-b0d3-457299c1ead8 | B30: Huevos Arizona | C30: 138 | D30: UN | G30: ti-incat-dbb4ab5d-d383-44df-bb1b-2819d297b20d | H30: Abarrotes | J30: ti-str-e3696e4b-7915-4d18-83e7-077d2c42d9bc,ti-str-e0754139-882f-4237-83fa-744442ed825f,ti-str-bbb1d66c-36dd-47af-85d8-583c26959146,ti-str-36f261ca-0b74-4d79-8a50-81324d9ac308 | K30: Principal,Stock Pasteleria,Stock Cocina,Stock Panaderia | L30: iva_19
A31: ti-ing-06898fd0-9448-431b-9bad-3526a93cf181 | B31: Ketchup kg | C31: 1550 | D31: KG | G31: ti-incat-dbb4ab5d-d383-44df-bb1b-2819d297b20d | H31: Abarrotes | J31: ti-str-e3696e4b-7915-4d18-83e7-077d2c42d9bc,ti-str-bbb1d66c-36dd-47af-85d8-583c26959146 | K31: Principal,Stock Cocina | L31: iva_19
A32: ti-ing-f3eeca8c-b308-4136-a438-0f68fc53c279 | B32: Lasagne Chef | C32: 3831.8 | D32: kg | G32: ti-incat-dbb4ab5d-d383-44df-bb1b-2819d297b20d | H32: Abarrotes | J32: ti-str-e3696e4b-7915-4d18-83e7-077d2c42d9bc,ti-str-bbb1d66c-36dd-47af-85d8-583c26959146 | K32: Principal,Stock Cocina | L32: iva_19
A33: ti-ing-20a9682d-4a6c-42c4-a3ed-312cab8df904 | B33: Laurel | C33: 75280 | D33: KG | G33: ti-incat-dbb4ab5d-d383-44df-bb1b-2819d297b20d | H33: Abarrotes | J33: ti-str-e3696e4b-7915-4d18-83e7-077d2c42d9bc,ti-str-bbb1d66c-36dd-47af-85d8-583c26959146 | K33: Principal,Stock Cocina | L33: iva_19
A34: ti-ing-772eef79-e2de-41fa-b52c-f097abd8b4a8 | B34: Leche Entera En Polvo | C34: 7079.167 | D34: KG | G34: ti-incat-dbb4ab5d-d383-44df-bb1b-2819d297b20d | H34: Abarrotes | J34: ti-str-e3696e4b-7915-4d18-83e7-077d2c42d9bc,ti-str-e0754139-882f-4237-83fa-744442ed825f,ti-str-36f261ca-0b74-4d79-8a50-81324d9ac308 | K34: Principal,Stock Pasteleria,Stock Panaderia | L34: iva_19
A35: ti-ing-a5f32751-2fe1-4388-acd1-977dd4d921a6 | B35: Lentejas (colacion personal) | C35: 2118 | D35: KG | G35: ti-incat-dbb4ab5d-d383-44df-bb1b-2819d297b20d | H35: Abarrotes | J35: ti-str-e3696e4b-7915-4d18-83e7-077d2c42d9bc,ti-str-bbb1d66c-36dd-47af-85d8-583c26959146 | K35: Principal,Stock Cocina | L35: iva_19
A36: ti-ing-0ec3786c-eec8-4a04-af8d-bda30eac5549 | B36: Levadura seca (Unidad) | C36: 1711 | D36: UN | G36: ti-incat-dbb4ab5d-d383-44df-bb1b-2819d297b20d | H36: Abarrotes | J36: ti-str-e3696e4b-7915-4d18-83e7-077d2c42d9bc,ti-str-e0754139-882f-4237-83fa-744442ed825f,ti-str-36f261ca-0b74-4d79-8a50-81324d9ac308 | K36: Principal,Stock Pasteleria,Stock Panaderia | L36: iva_19
A37: ti-ing-b41eeb59-c8ac-4580-b11d-bbd7dc537fd3 | B37: Linaza kg | C37: 2995 | D37: KG | G37: ti-incat-dbb4ab5d-d383-44df-bb1b-2819d297b20d | H37: Abarrotes | J37: ti-str-e3696e4b-7915-4d18-83e7-077d2c42d9bc,ti-str-36f261ca-0b74-4d79-8a50-81324d9ac308 | K37: Principal,Stock Panaderia | L37: iva_19
A38: ti-ing-69061f8d-e4d9-4fc4-b44e-0cd173ebf8f3 | B38: Maicena kg | C38: 1582 | D38: KG | G38: ti-incat-dbb4ab5d-d383-44df-bb1b-2819d297b20d | H38: Abarrotes | J38: ti-str-e3696e4b-7915-4d18-83e7-077d2c42d9bc,ti-str-e0754139-882f-4237-83fa-744442ed825f,ti-str-bbb1d66c-36dd-47af-85d8-583c26959146,ti-str-36f261ca-0b74-4d79-8a50-81324d9ac308 | K38: Principal,Stock Pasteleria,Stock Cocina,Stock Panaderia | L38: iva_19
A39: ti-ing-3dba6697-1589-49e0-8e6e-951b48b7d160 | B39: Mayonesa Hellmans | C39: 3989.362 | D39: Kg | G39: ti-incat-dbb4ab5d-d383-44df-bb1b-2819d297b20d | H39: Abarrotes | J39: ti-str-e3696e4b-7915-4d18-83e7-077d2c42d9bc,ti-str-bbb1d66c-36dd-47af-85d8-583c26959146 | K39: Principal,Stock Cocina | L39: iva_19
B40: Metabisulfito de sodio | C40: 14958 | D40: KG | G40: ti-incat-dbb4ab5d-d383-44df-bb1b-2819d297b20d | H40: Abarrotes | K40: Principal,Stock Cocina | L40: iva_19
A41: ti-ing-2758a41a-4b82-4e9c-b888-e1e3498bbd24 | B41: Miel | C41: 4117 | D41: UN | G41: ti-incat-dbb4ab5d-d383-44df-bb1b-2819d297b20d | H41: Abarrotes | J41: ti-str-e3696e4b-7915-4d18-83e7-077d2c42d9bc,ti-str-eafdd243-ca10-4e67-89d4-50a191eb8e12 | K41: Principal,Stock Servicio | L41: iva_19
A42: ti-ing-55acf21a-55c1-406f-a76b-b81347750e20 | B42: Mostaza | C42: 1336 | D42: KG | G42: ti-incat-dbb4ab5d-d383-44df-bb1b-2819d297b20d | H42: Abarrotes | J42: ti-str-e3696e4b-7915-4d18-83e7-077d2c42d9bc,ti-str-bbb1d66c-36dd-47af-85d8-583c26959146 | K42: Principal,Stock Cocina | L42: iva_19
...

Sheet principal
A1: Principal | B1: Principal
A2: ID PRODUCTO | B2: PRODUCTO | C2: STOCK | D2: PEDIDO | E2: UN MEDIDA | F2: CATEGORIA | G2: Valorizado Neto | H2: IVA (19%) | I2: Total Bruto | J2: PEDIDO
A3: =IFERROR(__xludf.DUMMYFUNCTION("FILTER('UNIVERSO PRODUCTOS'!A1:B958, ISNUMBER(SEARCH(A1, 'UNIVERSO PRODUCTOS'!K1:K958)))"),"ti-ing-b69bd6ae-ccae-4801-af83-bece901d304f") -> ti-ing-b69bd6ae-ccae-4801-af83-bece901d304f | B3: =IFERROR(__xludf.DUMMYFUNCTION("""COMPUTED_VALUE"""),"Aceite oliva extra virgen 5 lts") -> Aceite oliva extra virgen 5 lts | C3: 5 | D3: =IFERROR(__xludf.DUMMYFUNCTION("FILTER('UNIVERSO PRODUCTOS'!C1:C961, ISNUMBER(SEARCH(A1, 'UNIVERSO PRODUCTOS'!K1:K961)))"),4646.2) -> 4646.2 | E3: =IFERROR(__xludf.DUMMYFUNCTION("FILTER('UNIVERSO PRODUCTOS'!D1:D958, ISNUMBER(SEARCH(A1, 'UNIVERSO PRODUCTOS'!K1:K958)))"),"LT") -> LT | F3: =IFERROR(__xludf.DUMMYFUNCTION("FILTER('UNIVERSO PRODUCTOS'!H1:H958, ISNUMBER(SEARCH(A1, 'UNIVERSO PRODUCTOS'!K1:K958)))"),"Abarrotes") -> Abarrotes | G3: =(C3)*D3 -> 23231 | H3: =G3*19% -> 4413.89 | I3: =G3+H3 -> 27644.89
A4: =IFERROR(__xludf.DUMMYFUNCTION("""COMPUTED_VALUE"""),"ti-ing-5a1041f6-5fed-4ae0-8d00-dee7d47968a3") -> ti-ing-5a1041f6-5fed-4ae0-8d00-dee7d47968a3 | B4: =IFERROR(__xludf.DUMMYFUNCTION("""COMPUTED_VALUE"""),"Aceite vegetal 900 ml") -> Aceite vegetal 900 ml | C4: 22 | D4: =IFERROR(__xludf.DUMMYFUNCTION("""COMPUTED_VALUE"""),1540.6) -> 1540.6 | E4: =IFERROR(__xludf.DUMMYFUNCTION("""COMPUTED_VALUE"""),"UN") -> UN | F4: =IFERROR(__xludf.DUMMYFUNCTION("""COMPUTED_VALUE"""),"Abarrotes") -> Abarrotes | G4: =(C4)*D4 -> 33893.2 | H4: =G4*19% -> 6439.708 | I4: =G4+H4 -> 40332.908 | L4: Abarrotes | M4: Aseo | N4: Bebestibles | O4: Cafetería | P4: Carnes y Aves | Q4: Desechables | R4: Frutas y Verduras | S4: Harinas | T4: Ovolacteos | U4: Pastelería | V4: Pescados y Mariscos | W4: P.Terminados | X4: Té | Y4: Valor Neto
A5: =IFERROR(__xludf.DUMMYFUNCTION("""COMPUTED_VALUE"""),"ti-ing-581e5046-d41b-44fd-981a-fa5ec2c4d4ba") -> ti-ing-581e5046-d41b-44fd-981a-fa5ec2c4d4ba | B5: =IFERROR(__xludf.DUMMYFUNCTION("""COMPUTED_VALUE"""),"Ajinomoto") -> Ajinomoto | C5: 0 | D5: =IFERROR(__xludf.DUMMYFUNCTION("""COMPUTED_VALUE"""),3354) -> 3354 | E5: =IFERROR(__xludf.DUMMYFUNCTION("""COMPUTED_VALUE"""),"kg") -> kg | F5: =IFERROR(__xludf.DUMMYFUNCTION("""COMPUTED_VALUE"""),"Abarrotes") -> Abarrotes | G5: =(C5)*D5 -> 0 | H5: =G5*19% -> 0 | I5: =G5+H5 -> 0
A6: =IFERROR(__xludf.DUMMYFUNCTION("""COMPUTED_VALUE"""),"ti-ing-65292276-c9a9-4569-b8ff-19a5a3fea424") -> ti-ing-65292276-c9a9-4569-b8ff-19a5a3fea424 | B6: =IFERROR(__xludf.DUMMYFUNCTION("""COMPUTED_VALUE"""),"Anis kg") -> Anis kg | C6: 0 | D6: =IFERROR(__xludf.DUMMYFUNCTION("""COMPUTED_VALUE"""),13854) -> 13854 | E6: =IFERROR(__xludf.DUMMYFUNCTION("""COMPUTED_VALUE"""),"Kg") -> Kg | F6: =IFERROR(__xludf.DUMMYFUNCTION("""COMPUTED_VALUE"""),"Abarrotes") -> Abarrotes | G6: =(C6)*D6 -> 0 | H6: =G6*19% -> 0 | I6: =G6+H6 -> 0 | L6: =SUM(G3:G69) -> 614037.05 | M6: =SUM(G70:G103) -> 181265.8 | N6: =SUM(G104:G124) -> 600175.24 | O6: =SUM(G125:G140) -> 601709.13 | P6: =SUM(G288) -> 55904.425 | Q6: =SUM(G141:G216) -> 6014459.6 | R6: =SUM(G217:G218) -> 109881 | S6: =SUM(G219:G222) -> 513224 | T6: =SUM(G223:G240,G289:G290) -> 1024809.5 | U6: =SUM(G241:G276) -> 788878.55 | W6: =SUM(G277) -> 0 | X6: =SUM(G278:G288) -> 75720.425 | Y6: =SUM(L6:X6) -> 10580065
A7: =IFERROR(__xludf.DUMMYFUNCTION("""COMPUTED_VALUE"""),"ti-ing-bfd5d10e-d265-4e6e-b05a-79c836269380") -> ti-ing-bfd5d10e-d265-4e6e-b05a-79c836269380 | B7: =IFERROR(__xludf.DUMMYFUNCTION("""COMPUTED_VALUE"""),"Arroz (colacion)") -> Arroz (colacion) | C7: 15 | D7: =IFERROR(__xludf.DUMMYFUNCTION("""COMPUTED_VALUE"""),905) -> 905 | E7: =IFERROR(__xludf.DUMMYFUNCTION("""COMPUTED_VALUE"""),"KG") -> KG | F7: =IFERROR(__xludf.DUMMYFUNCTION("""COMPUTED_VALUE"""),"Abarrotes") -> Abarrotes | G7: =(C7)*D7 -> 13575 | H7: =G7*19% -> 2579.25 | I7: =G7+H7 -> 16154.25
A8: =IFERROR(__xludf.DUMMYFUNCTION("""COMPUTED_VALUE"""),"ti-ing-5c316419-1759-4d90-bb2e-e9025a87d122") -> ti-ing-5c316419-1759-4d90-bb2e-e9025a87d122 | B8: =IFERROR(__xludf.DUMMYFUNCTION("""COMPUTED_VALUE"""),"Atun Coliseo Al Agua") -> Atun Coliseo Al Agua | C8: 0 | D8: =IFERROR(__xludf.DUMMYFUNCTION("""COMPUTED_VALUE"""),879) -> 879 | E8: =IFERROR(__xludf.DUMMYFUNCTION("""COMPUTED_VALUE"""),"UN") -> UN | F8: =IFERROR(__xludf.DUMMYFUNCTION("""COMPUTED_VALUE"""),"Abarrotes") -> Abarrotes | G8: =(C8)*D8 -> 0 | H8: =G8*19% -> 0 | I8: =G8+H8 -> 0 | L8: Abarrotes | M8: Aseo | N8: Bebestibles | O8: Cafetería | P8: Carnes y Aves | Q8: Desechables | R8: Frutas y Verduras | S8: Harinas | T8: Ovolacteos | U8: Pastelería | V8: Pescados y Mariscos | W8: P.Terminados | X8: Té | Y8: Valor Bruto
A9: =IFERROR(__xludf.DUMMYFUNCTION("""COMPUTED_VALUE"""),"ti-ing-363a5ec1-8d6b-4612-be6a-7a19b61ab7e2") -> ti-ing-363a5ec1-8d6b-4612-be6a-7a19b61ab7e2 | B9: =IFERROR(__xludf.DUMMYFUNCTION("""COMPUTED_VALUE"""),"Atun Dorasol Al Agua") -> Atun Dorasol Al Agua | C9: 0 | D9: =IFERROR(__xludf.DUMMYFUNCTION("""COMPUTED_VALUE"""),879) -> 879 | E9: =IFERROR(__xludf.DUMMYFUNCTION("""COMPUTED_VALUE"""),"UN") -> UN | F9: =IFERROR(__xludf.DUMMYFUNCTION("""COMPUTED_VALUE"""),"Abarrotes") -> Abarrotes | G9: =(C9)*D9 -> 0 | H9: =G9*19% -> 0 | I9: =G9+H9 -> 0
A10: =IFERROR(__xludf.DUMMYFUNCTION("""COMPUTED_VALUE"""),"ti-ing-c1414efc-1614-40c6-a7e8-2f6efb3e0401") -> ti-ing-c1414efc-1614-40c6-a7e8-2f6efb3e0401 | B10: =IFERROR(__xludf.DUMMYFUNCTION("""COMPUTED_VALUE"""),"Avena") -> Avena | C10: 7 | D10: =IFERROR(__xludf.DUMMYFUNCTION("""COMPUTED_VALUE"""),1050) -> 1050 | E10: =IFERROR(__xludf.DUMMYFUNCTION("""COMPUTED_VALUE"""),"KG") -> KG | F10: =IFERROR(__xludf.DUMMYFUNCTION("""COMPUTED_VALUE"""),"Abarrotes") -> Abarrotes | G10: =(C10)*D10 -> 7350 | H10: =G10*19% -> 1396.5 | I10: =G10+H10 -> 8746.5 | L10: =SUM(I3:I69) -> 730704.09 | M10: =SUM(I70:I103) -> 215706.31 | N10: =SUM(I104:I124) -> 696885.23 | O10: =SUM(I125:I140) -> 716033.87 | P10: =SUM(I288) -> 66526.265 | Q10: =SUM(I141:I216) -> 7157206.9 | R10: =SUM(I217:I218) -> 130758.39 | S10: =SUM(I219:I222) -> 610736.56 | T10: =SUM(I223:I240,I289:I290) -> 1219523.2 | U10: =SUM(I241:I276) -> 938765.48 | W10: =SUM(I277) -> 0 | X10: =SUM(I278:I288) -> 90107.305 | Y10: =SUM(L10:X10) -> 12572954
A11: =IFERROR(__xludf.DUMMYFUNCTION("""COMPUTED_VALUE"""),"ti-ing-531d1d9b-814d-49bc-9bbf-06be4ae2e6d5") -> ti-ing-531d1d9b-814d-49bc-9bbf-06be4ae2e6d5 | B11: =IFERROR(__xludf.DUMMYFUNCTION("""COMPUTED_VALUE"""),"Azucar blanca") -> Azucar blanca | C11: 50 | D11: =IFERROR(__xludf.DUMMYFUNCTION("""COMPUTED_VALUE"""),939.9985) -> 939.9985 | E11: =IFERROR(__xludf.DUMMYFUNCTION("""COMPUTED_VALUE"""),"KG") -> KG | F11: =IFERROR(__xludf.DUMMYFUNCTION("""COMPUTED_VALUE"""),"Abarrotes") -> Abarrotes | G11: =(C11)*D11 -> 46999.925 | H11: =G11*19% -> 8929.9857 | I11: =G11+H11 -> 55929.911
B12: =IFERROR(__xludf.DUMMYFUNCTION("""COMPUTED_VALUE"""),"Azúcar blanca por kilo") -> Azúcar blanca por kilo | C12: 0 | D12: =IFERROR(__xludf.DUMMYFUNCTION("""COMPUTED_VALUE"""),930) -> 930 | E12: =IFERROR(__xludf.DUMMYFUNCTION("""COMPUTED_VALUE"""),"KG") -> KG | F12: =IFERROR(__xludf.DUMMYFUNCTION("""COMPUTED_VALUE"""),"Abarrotes") -> Abarrotes | G12: =(C12)*D12 -> 0 | H12: =G12*19% -> 0 | I12: =G12+H12 -> 0 | L12: =(L10*100)/$Y$10 -> 5.8117139 | M12: =(M10*100)/$Y$10 -> 1.7156375 | N12: =(N10*100)/$Y$10 -> 5.5427329 | O12: =(O10*100)/$Y$10 -> 5.6950331 | P12: =(P10*100)/$Y$10 -> 0.52912201 | Q12: =(Q10*100)/$Y$10 -> 56.925422 | R12: =(R10*100)/$Y$10 -> 1.0399974 | S12: =(S10*100)/$Y$10 -> 4.8575424 | ... X12: =(X10*100)/$Y$10 -> 0.71667571
A13: =IFERROR(__xludf.DUMMYFUNCTION("""COMPUTED_VALUE"""),"ti-ing-c4486ce7-85c4-49c5-ac82-4d98b0798d01") -> ti-ing-c4486ce7-85c4-49c5-ac82-4d98b0798d01 | B13: =IFERROR(__xludf.DUMMYFUNCTION("""COMPUTED_VALUE"""),"Azucar rubia") -> Azucar rubia | C13: 5 | D13: =IFERROR(__xludf.DUMMYFUNCTION("""COMPUTED_VALUE"""),1047) -> 1047 | E13: =IFERROR(__xludf.DUMMYFUNCTION("""COMPUTED_VALUE"""),"KG") -> KG | F13: =IFERROR(__xludf.DUMMYFUNCTION("""COMPUTED_VALUE"""),"Abarrotes") -> Abarrotes | G13: =(C13)*D13 -> 5235 | H13: =G13*19% -> 994.65 | I13: =G13+H13 -> 6229.65
A14: =IFERROR(__xludf.DUMMYFUNCTION("""COMPUTED_VALUE"""),"ti-ing-63a7f9f9-77ff-45f4-9e3f-3feff0b73432") -> ti-ing-63a7f9f9-77ff-45f4-9e3f-3feff0b73432 | B14: =IFERROR(__xludf.DUMMYFUNCTION("""COMPUTED_VALUE"""),"Café tarro grande (desayuno)") -> Café tarro grande (desayuno) | C14: 4 | D14: =IFERROR(__xludf.DUMMYFUNCTION("""COMPUTED_VALUE"""),12032) -> 12032 | E14: =IFERROR(__xludf.DUMMYFUNCTION("""COMPUTED_VALUE"""),"UN") -> UN | F14: =IFERROR(__xludf.DUMMYFUNCTION("""COMPUTED_VALUE"""),"Abarrotes") -> Abarrotes | G14: =(C14)*D14 -> 48128 | H14: =G14*19% -> 9144.32 | I14: =G14+H14 -> 57272.32
A15: =IFERROR(__xludf.DUMMYFUNCTION("""COMPUTED_VALUE"""),"ti-ing-f57e1d6d-2d59-440c-a741-794a5d5d1359") -> ti-ing-f57e1d6d-2d59-440c-a741-794a5d5d1359 | B15: =IFERROR(__xludf.DUMMYFUNCTION("""COMPUTED_VALUE"""),"Chia kg") -> Chia kg | C15: 0 | D15: =IFERROR(__xludf.DUMMYFUNCTION("""COMPUTED_VALUE"""),4152) -> 4152 | E15: =IFERROR(__xludf.DUMMYFUNCTION("""COMPUTED_VALUE"""),"UN") -> UN | F15: =IFERROR(__xludf.DUMMYFUNCTION("""COMPUTED_VALUE"""),"Abarrotes") -> Abarrotes | G15: =(C15)*D15 -> 0 | H15: =G15*19% -> 0 | I15: =G15+H15 -> 0
A16: =IFERROR(__xludf.DUMMYFUNCTION("""COMPUTED_VALUE"""),"ti-ing-b908bdf8-4d68-4e4a-bca8-67edb76d6236") -> ti-ing-b908bdf8-4d68-4e4a-bca8-67edb76d6236 | B16: =IFERROR(__xludf.DUMMYFUNCTION("""COMPUTED_VALUE"""),"Chips Chocolate Negro kg") -> Chips Chocolate Negro kg | C16: 9 | D16: =IFERROR(__xludf.DUMMYFUNCTION("""COMPUTED_VALUE"""),6977.75) -> 6977.75 | E16: =IFERROR(__xludf.DUMMYFUNCTION("""COMPUTED_VALUE"""),"KG") -> KG | F16: =IFERROR(__xludf.DUMMYFUNCTION("""COMPUTED_VALUE"""),"Abarrotes") -> Abarrotes | G16: =(C16)*D16 -> 62799.75 | H16: =G16*19% -> 11931.952 | I16: =G16+H16 -> 74731.702
A17: =IFERROR(__xludf.DUMMYFUNCTION("""COMPUTED_VALUE"""),"ti-ing-89800579-a778-4a4e-8895-e0cc7ed6a986") -> ti-ing-89800579-a778-4a4e-8895-e0cc7ed6a986 | B17: =IFERROR(__xludf.DUMMYFUNCTION("""COMPUTED_VALUE"""),"Coco Laminado") -> Coco Laminado | C17: 2 | D17: =IFERROR(__xludf.DUMMYFUNCTION("""COMPUTED_VALUE"""),8474) -> 8474 | E17: =IFERROR(__xludf.DUMMYFUNCTION("""COMPUTED_VALUE"""),"KG") -> KG | F17: =IFERROR(__xludf.DUMMYFUNCTION("""COMPUTED_VALUE"""),"Abarrotes") -> Abarrotes | G17: =(C17)*D17 -> 16948 | H17: =G17*19% -> 3220.12 | I17: =G17+H17 -> 20168.12
A18: =IFERROR(__xludf.DUMMYFUNCTION("""COMPUTED_VALUE"""),"ti-ing-a396335b-a1d5-46a1-874a-de8bd1a3a0de") -> ti-ing-a396335b-a1d5-46a1-874a-de8bd1a3a0de | B18: =IFERROR(__xludf.DUMMYFUNCTION("""COMPUTED_VALUE"""),"Coco Rallado") -> Coco Rallado | C18: 3 | D18: =IFERROR(__xludf.DUMMYFUNCTION("""COMPUTED_VALUE"""),4188) -> 4188 | E18: =IFERROR(__xludf.DUMMYFUNCTION("""COMPUTED_VALUE"""),"KG") -> KG | F18: =IFERROR(__xludf.DUMMYFUNCTION("""COMPUTED_VALUE"""),"Abarrotes") -> Abarrotes | G18: =(C18)*D18 -> 12564 | H18: =G18*19% -> 2387.16 | I18: =G18+H18 -> 14951.16
A19: =IFERROR(__xludf.DUMMYFUNCTION("""COMPUTED_VALUE"""),"ti-ing-280562df-e2c6-469c-bfaf-8f7361fb5c74") -> ti-ing-280562df-e2c6-469c-bfaf-8f7361fb5c74 | B19: =IFERROR(__xludf.DUMMYFUNCTION("""COMPUTED_VALUE"""),"COMINO") -> COMINO | C19: 0 | D19: =IFERROR(__xludf.DUMMYFUNCTION("""COMPUTED_VALUE"""),5250) -> 5250 | E19: =IFERROR(__xludf.DUMMYFUNCTION("""COMPUTED_VALUE"""),"KG") -> KG | F19: =IFERROR(__xludf.DUMMYFUNCTION("""COMPUTED_VALUE"""),"Abarrotes") -> Abarrotes | G19: =(C19)*D19 -> 0 | H19: =G19*19% -> 0 | I19: =G19+H19 -> 0
A20: =IFERROR(__xludf.DUMMYFUNCTION("""COMPUTED_VALUE"""),"ti-ing-55e22a4e-70ba-4bfe-9ef6-78d09a6c71b6") -> ti-ing-55e22a4e-70ba-4bfe-9ef6-78d09a6c71b6 | B20: =IFERROR(__xludf.DUMMYFUNCTION("""COMPUTED_VALUE"""),"Curcuma") -> Curcuma | C20: 1 | D20: =IFERROR(__xludf.DUMMYFUNCTION("""COMPUTED_VALUE"""),5437) -> 5437 | E20: =IFERROR(__xludf.DUMMYFUNCTION("""COMPUTED_VALUE"""),"KG") -> KG | F20: =IFERROR(__xludf.DUMMYFUNCTION("""COMPUTED_VALUE"""),"Abarrotes") -> Abarrotes | G20: =(C20)*D20 -> 5437 | H20: =G20*19% -> 1033.03 | I20: =G20+H20 -> 6470.03
A21: =IFERROR(__xludf.DUMMYFUNCTION("""COMPUTED_VALUE"""),"ti-ing-064cb0f3-6635-4de8-915c-d57502a19286") -> ti-ing-064cb0f3-6635-4de8-915c-d57502a19286 | B21: =IFERROR(__xludf.DUMMYFUNCTION("""COMPUTED_VALUE"""),"Esencia vainilla") -> Esencia vainilla | C21: 0 | D21: =IFERROR(__xludf.DUMMYFUNCTION("""COMPUTED_VALUE"""),1000) -> 1000 | E21: =IFERROR(__xludf.DUMMYFUNCTION("""COMPUTED_VALUE"""),"LT") -> LT | F21: =IFERROR(__xludf.DUMMYFUNCTION("""COMPUTED_VALUE"""),"Abarrotes") -> Abarrotes | G21: =(C21)*D21 -> 0 | H21: =G21*19% -> 0 | I21: =G21+H21 -> 0
A22: =IFERROR(__xludf.DUMMYFUNCTION("""COMPUTED_VALUE"""),"ti-ing-2fbc1c56-3286-4d64-8ddd-b547296361a3") -> ti-ing-2fbc1c56-3286-4d64-8ddd-b547296361a3 | B22: =IFERROR(__xludf.DUMMYFUNCTION("""COMPUTED_VALUE"""),"Espaguetti") -> Espaguetti | C22: 2 | D22: =IFERROR(__xludf.DUMMYFUNCTION("""COMPUTED_VALUE"""),407) -> 407 | E22: =IFERROR(__xludf.DUMMYFUNCTION("""COMPUTED_VALUE"""),"UN") -> UN | F22: =IFERROR(__xludf.DUMMYFUNCTION("""COMPUTED_VALUE"""),"Abarrotes") -> Abarrotes | G22: =(C22)*D22 -> 814 | H22: =G22*19% -> 154.66 | I22: =G22+H22 -> 968.66
A23: =IFERROR(__xludf.DUMMYFUNCTION("""COMPUTED_VALUE"""),"ti-ing-446530ff-42dc-41f9-9208-1b6c8dded86f") -> ti-ing-446530ff-42dc-41f9-9208-1b6c8dded86f | B23: =IFERROR(__xludf.DUMMYFUNCTION("""COMPUTED_VALUE"""),"Espirales") -> Espirales | C23: 0 | D23: =IFERROR(__xludf.DUMMYFUNCTION("""COMPUTED_VALUE"""),399) -> 399 | E23: =IFERROR(__xludf.DUMMYFUNCTION("""COMPUTED_VALUE"""),"UN") -> UN | F23: =IFERROR(__xludf.DUMMYFUNCTION("""COMPUTED_VALUE"""),"Abarrotes") -> Abarrotes | G23: =(C23)*D23 -> 0 | H23: =G23*19% -> 0 | I23: =G23+H23 -> 0
A24: =IFERROR(__xludf.DUMMYFUNCTION("""COMPUTED_VALUE"""),"ti-ing-150d078f-94cc-4527-a524-b16516d0adfa") -> ti-ing-150d078f-94cc-4527-a524-b16516d0adfa | B24: =IFERROR(__xludf.DUMMYFUNCTION("""COMPUTED_VALUE"""),"Fruta Confitada") -> Fruta Confitada | C24: 4 | D24: =IFERROR(__xludf.DUMMYFUNCTION("""COMPUTED_VALUE"""),3500) -> 3500 | E24: =IFERROR(__xludf.DUMMYFUNCTION("""COMPUTED_VALUE"""),"KG") -> KG | F24: =IFERROR(__xludf.DUMMYFUNCTION("""COMPUTED_VALUE"""),"Abarrotes") -> Abarrotes | G24: =(C24)*D24 -> 14000 | H24: =G24*19% -> 2660 | I24: =G24+H24 -> 16660
A25: =IFERROR(__xludf.DUMMYFUNCTION("""COMPUTED_VALUE"""),"ti-ing-11a33780-09cc-47f7-b11c-89e4b6139bb9") -> ti-ing-11a33780-09cc-47f7-b11c-89e4b6139bb9 | B25: =IFERROR(__xludf.DUMMYFUNCTION("""COMPUTED_VALUE"""),"Garbanzos") -> Garbanzos | C25: 1 | D25: =IFERROR(__xludf.DUMMYFUNCTION("""COMPUTED_VALUE"""),2291.25) -> 2291.25 | E25: =IFERROR(__xludf.DUMMYFUNCTION("""COMPUTED_VALUE"""),"KG") -> KG | F25: =IFERROR(__xludf.DUMMYFUNCTION("""COMPUTED_VALUE"""),"Abarrotes") -> Abarrotes | G25: =(C25)*D25 -> 2291.25 | H25: =G25*19% -> 435.3375 | I25: =G25+H25 -> 2726.5875
A26: =IFERROR(__xludf.DUMMYFUNCTION("""COMPUTED_VALUE"""),"ti-ing-af062f27-295c-456a-9ce5-77fbb725f339") -> ti-ing-af062f27-295c-456a-9ce5-77fbb725f339 | B26: =IFERROR(__xludf.DUMMYFUNCTION("""COMPUTED_VALUE"""),"Helado Chocolate") -> Helado Chocolate | C26: 0 | D26: =IFERROR(__xludf.DUMMYFUNCTION("""COMPUTED_VALUE"""),2360.6) -> 2360.6 | E26: =IFERROR(__xludf.DUMMYFUNCTION("""COMPUTED_VALUE"""),"LT") -> LT | F26: =IFERROR(__xludf.DUMMYFUNCTION("""COMPUTED_VALUE"""),"Abarrotes") -> Abarrotes | G26: =(C26)*D26 -> 0 | H26: =G26*19% -> 0 | I26: =G26+H26 -> 0
B27: =IFERROR(__xludf.DUMMYFUNCTION("""COMPUTED_VALUE"""),"Helado frutilla") -> Helado frutilla | C27: 0 | D27: =IFERROR(__xludf.DUMMYFUNCTION("""COMPUTED_VALUE"""),3469) -> 3469 | E27: =IFERROR(__xludf.DUMMYFUNCTION("""COMPUTED_VALUE"""),"LT") -> LT | F27: =IFERROR(__xludf.DUMMYFUNCTION("""COMPUTED_VALUE"""),"Abarrotes") -> Abarrotes | G27: =(C27)*D27 -> 0 | H27: =G27*19% -> 0 | I27: =G27+H27 -> 0
A28: =IFERROR(__xludf.DUMMYFUNCTION("""COMPUTED_VALUE"""),"ti-ing-12dbd538-5012-4d25-8c02-7d0b4f3fdf45") -> ti-ing-12dbd538-5012-4d25-8c02-7d0b4f3fdf45 | B28: =IFERROR(__xludf.DUMMYFUNCTION("""COMPUTED_VALUE"""),"Helado Vainilla") -> Helado Vainilla | C28: 0 | D28: =IFERROR(__xludf.DUMMYFUNCTION("""COMPUTED_VALUE"""),2979) -> 2979 | E28: =IFERROR(__xludf.DUMMYFUNCTION("""COMPUTED_VALUE"""),"LT") -> LT | F28: =IFERROR(__xludf.DUMMYFUNCTION("""COMPUTED_VALUE"""),"Abarrotes") -> Abarrotes | G28: =(C28)*D28 -> 0 | H28: =G28*19% -> 0 | I28: =G28+H28 -> 0
A29: =IFERROR(__xludf.DUMMYFUNCTION("""COMPUTED_VALUE"""),"ti-ing-e6ff2cd2-0729-44b9-b0d3-457299c1ead8") -> ti-ing-e6ff2cd2-0729-44b9-b0d3-457299c1ead8 | B29: =IFERROR(__xludf.DUMMYFUNCTION("""COMPUTED_VALUE"""),"Huevos Arizona") -> Huevos Arizona | C29: 1.08 | D29: =IFERROR(__xludf.DUMMYFUNCTION("""COMPUTED_VALUE"""),138) -> 138 | E29: =IFERROR(__xludf.DUMMYFUNCTION("""COMPUTED_VALUE"""),"UN") -> UN | F29: =IFERROR(__xludf.DUMMYFUNCTION("""COMPUTED_VALUE"""),"Abarrotes") -> Abarrotes | G29: =(C29)*D29 -> 149.04 | H29: =G29*19% -> 28.3176 | I29: =G29+H29 -> 177.3576
A30: =IFERROR(__xludf.DUMMYFUNCTION("""COMPUTED_VALUE"""),"ti-ing-06898fd0-9448-431b-9bad-3526a93cf181") -> ti-ing-06898fd0-9448-431b-9bad-3526a93cf181 | B30: =IFERROR(__xludf.DUMMYFUNCTION("""COMPUTED_VALUE"""),"Ketchup kg") -> Ketchup kg | C30: 0 | D30: =IFERROR(__xludf.DUMMYFUNCTION("""COMPUTED_VALUE"""),1550) -> 1550 | E30: =IFERROR(__xludf.DUMMYFUNCTION("""COMPUTED_VALUE"""),"KG") -> KG | F30: =IFERROR(__xludf.DUMMYFUNCTION("""COMPUTED_VALUE"""),"Abarrotes") -> Abarrotes | G30: =(C30)*D30 -> 0 | H30: =G30*19% -> 0 | I30: =G30+H30 -> 0
A31: =IFERROR(__xludf.DUMMYFUNCTION("""COMPUTED_VALUE"""),"ti-ing-f3eeca8c-b308-4136-a438-0f68fc53c279") -> ti-ing-f3eeca8c-b308-4136-a438-0f68fc53c279 | B31: =IFERROR(__xludf.DUMMYFUNCTION("""COMPUTED_VALUE"""),"Lasagne Chef") -> Lasagne Chef | C31: 6.6 | D31: =IFERROR(__xludf.DUMMYFUNCTION("""COMPUTED_VALUE"""),3831.8) -> 3831.8 | E31: =IFERROR(__xludf.DUMMYFUNCTION("""COMPUTED_VALUE"""),"kg") -> kg | F31: =IFERROR(__xludf.DUMMYFUNCTION("""COMPUTED_VALUE"""),"Abarrotes") -> Abarrotes | G31: =(C31)*D31 -> 25289.88 | H31: =G31*19% -> 4805.0772 | I31: =G31+H31 -> 30094.957
A32: =IFERROR(__xludf.DUMMYFUNCTION("""COMPUTED_VALUE"""),"ti-ing-20a9682d-4a6c-42c4-a3ed-312cab8df904") -> ti-ing-20a9682d-4a6c-42c4-a3ed-312cab8df904 | B32: =IFERROR(__xludf.DUMMYFUNCTION("""COMPUTED_VALUE"""),"Laurel") -> Laurel | C32: 0.3 | D32: =IFERROR(__xludf.DUMMYFUNCTION("""COMPUTED_VALUE"""),75280) -> 75280 | E32: =IFERROR(__xludf.DUMMYFUNCTION("""COMPUTED_VALUE"""),"KG") -> KG | F32: =IFERROR(__xludf.DUMMYFUNCTION("""COMPUTED_VALUE"""),"Abarrotes") -> Abarrotes | G32: =(C32)*D32 -> 22584 | H32: =G32*19% -> 4290.96 | I32: =G32+H32 -> 26874.96
A33: =IFERROR(__xludf.DUMMYFUNCTION("""COMPUTED_VALUE"""),"ti-ing-772eef79-e2de-41fa-b52c-f097abd8b4a8") -> ti-ing-772eef79-e2de-41fa-b52c-f097abd8b4a8 | B33: =IFERROR(__xludf.DUMMYFUNCTION("""COMPUTED_VALUE"""),"Leche Entera En Polvo") -> Leche Entera En Polvo | C33: 7.2 | D33: =IFERROR(__xludf.DUMMYFUNCTION("""COMPUTED_VALUE"""),7079.167) -> 7079.167 | E33: =IFERROR(__xludf.DUMMYFUNCTION("""COMPUTED_VALUE"""),"KG") -> KG | F33: =IFERROR(__xludf.DUMMYFUNCTION("""COMPUTED_VALUE"""),"Abarrotes") -> Abarrotes | G33: =(C33)*D33 -> 50970.002 | H33: =G33*19% -> 9684.3005 | I33: =G33+H33 -> 60654.303
A34: =IFERROR(__xludf.DUMMYFUNCTION("""COMPUTED_VALUE"""),"ti-ing-a5f32751-2fe1-4388-acd1-977dd4d921a6") -> ti-ing-a5f32751-2fe1-4388-acd1-977dd4d921a6 | B34: =IFERROR(__xludf.DUMMYFUNCTION("""COMPUTED_VALUE"""),"Lentejas (colacion personal)") -> Lentejas (colacion personal) | C34: 0 | D34: =IFERROR(__xludf.DUMMYFUNCTION("""COMPUTED_VALUE"""),2118) -> 2118 | E34: =IFERROR(__xludf.DUMMYFUNCTION("""COMPUTED_VALUE"""),"KG") -> KG | F34: =IFERROR(__xludf.DUMMYFUNCTION("""COMPUTED_VALUE"""),"Abarrotes") -> Abarrotes | G34: =(C34)*D34 -> 0 | H34: =G34*19% -> 0 | I34: =G34+H34 -> 0
A35: =IFERROR(__xludf.DUMMYFUNCTION("""COMPUTED_VALUE"""),"ti-ing-0ec3786c-eec8-4a04-af8d-bda30eac5549") -> ti-ing-0ec3786c-eec8-4a04-af8d-bda30eac5549 | B35: =IFERROR(__xludf.DUMMYFUNCTION("""COMPUTED_VALUE"""),"Levadura seca (Unidad)") -> Levadura seca (Unidad) | C35: 8 | D35: =IFERROR(__xludf.DUMMYFUNCTION("""COMPUTED_VALUE"""),1711) -> 1711 | E35: =IFERROR(__xludf.DUMMYFUNCTION("""COMPUTED_VALUE"""),"UN") -> UN | F35: =IFERROR(__xludf.DUMMYFUNCTION("""COMPUTED_VALUE"""),"Abarrotes") -> Abarrotes | G35: =(C35)*D35 -> 13688 | H35: =G35*19% -> 2600.72 | I35: =G35+H35 -> 16288.72
A36: =IFERROR(__xludf.DUMMYFUNCTION("""COMPUTED_VALUE"""),"ti-ing-b41eeb59-c8ac-4580-b11d-bbd7dc537fd3") -> ti-ing-b41eeb59-c8ac-4580-b11d-bbd7dc537fd3 | B36: =IFERROR(__xludf.DUMMYFUNCTION("""COMPUTED_VALUE"""),"Linaza kg") -> Linaza kg | C36: 1 | D36: =IFERROR(__xludf.DUMMYFUNCTION("""COMPUTED_VALUE"""),2995) -> 2995 | E36: =IFERROR(__xludf.DUMMYFUNCTION("""COMPUTED_VALUE"""),"KG") -> KG | F36: =IFERROR(__xludf.DUMMYFUNCTION("""COMPUTED_VALUE"""),"Abarrotes") -> Abarrotes | G36: =(C36)*D36 -> 2995 | H36: =G36*19% -> 569.05 | I36: =G36+H36 -> 3564.05
A37: =IFERROR(__xludf.DUMMYFUNCTION("""COMPUTED_VALUE"""),"ti-ing-69061f8d-e4d9-4fc4-b44e-0cd173ebf8f3") -> ti-ing-69061f8d-e4d9-4fc4-b44e-0cd173ebf8f3 | B37: =IFERROR(__xludf.DUMMYFUNCTION("""COMPUTED_VALUE"""),"Maicena kg") -> Maicena kg | C37: 2 | D37: =IFERROR(__xludf.DUMMYFUNCTION("""COMPUTED_VALUE"""),1582) -> 1582 | E37: =IFERROR(__xludf.DUMMYFUNCTION("""COMPUTED_VALUE"""),"KG") -> KG | F37: =IFERROR(__xludf.DUMMYFUNCTION("""COMPUTED_VALUE"""),"Abarrotes") -> Abarrotes | G37: =(C37)*D37 -> 3164 | H37: =G37*19% -> 601.16 | I37: =G37+H37 -> 3765.16
A38: =IFERROR(__xludf.DUMMYFUNCTION("""COMPUTED_VALUE"""),"ti-ing-3dba6697-1589-49e0-8e6e-951b48b7d160") -> ti-ing-3dba6697-1589-49e0-8e6e-951b48b7d160 | B38: =IFERROR(__xludf.DUMMYFUNCTION("""COMPUTED_VALUE"""),"Mayonesa Hellmans") -> Mayonesa Hellmans | C38: 5.7 | D38: =IFERROR(__xludf.DUMMYFUNCTION("""COMPUTED_VALUE"""),3989.362) -> 3989.362 | E38: =IFERROR(__xludf.DUMMYFUNCTION("""COMPUTED_VALUE"""),"Kg") -> Kg | F38: =IFERROR(__xludf.DUMMYFUNCTION("""COMPUTED_VALUE"""),"Abarrotes") -> Abarrotes | G38: =(C38)*D38 -> 22739.363 | H38: =G38*19% -> 4320.479 | I38: =G38+H38 -> 27059.842
B39: =IFERROR(__xludf.DUMMYFUNCTION("""COMPUTED_VALUE"""),"Metabisulfito de sodio") -> Metabisulfito de sodio | C39: 0 | D39: =IFERROR(__xludf.DUMMYFUNCTION("""COMPUTED_VALUE"""),14958) -> 14958 | E39: =IFERROR(__xludf.DUMMYFUNCTION("""COMPUTED_VALUE"""),"KG") -> KG | F39: =IFERROR(__xludf.DUMMYFUNCTION("""COMPUTED_VALUE"""),"Abarrotes") -> Abarrotes | G39: =(C39)*D39 -> 0 | H39: =G39*19% -> 0 | I39: =G39+H39 -> 0
A40: =IFERROR(__xludf.DUMMYFUNCTION("""COMPUTED_VALUE"""),"ti-ing-2758a41a-4b82-4e9c-b888-e1e3498bbd24") -> ti-ing-2758a41a-4b82-4e9c-b888-e1e3498bbd24 | B40: =IFERROR(__xludf.DUMMYFUNCTION("""COMPUTED_VALUE"""),"Miel") -> Miel | C40: 1 | D40: =IFERROR(__xludf.DUMMYFUNCTION("""COMPUTED_VALUE"""),4117) -> 4117 | E40: =IFERROR(__xludf.DUMMYFUNCTION("""COMPUTED_VALUE"""),"UN") -> UN | F40: =IFERROR(__xludf.DUMMYFUNCTION("""COMPUTED_VALUE"""),"Abarrotes") -> Abarrotes | G40: =(C40)*D40 -> 4117 | H40: =G40*19% -> 782.23 | I40: =G40+H40 -> 4899.23
...

Sheet cocina
A1: Stock Cocina | B1: Stock Cocina
A2: ID PRODUCTO | B2: PRODUCTO | C2: STOCK | D2: PEDIDO | E2: UN MEDIDA | F2: CATEGORIA | G2: Valorizado Neto | H2: IVA (19%) | I2: Total Bruto | J2: PEDIDO
A3: =IFERROR(__xludf.DUMMYFUNCTION("FILTER('UNIVERSO PRODUCTOS'!A1:B958, ISNUMBER(SEARCH(A1, 'UNIVERSO PRODUCTOS'!K1:K958))) "),"ti-ing-b69bd6ae-ccae-4801-af83-bece901d304f") -> ti-ing-b69bd6ae-ccae-4801-af83-bece901d304f | B3: =IFERROR(__xludf.DUMMYFUNCTION("""COMPUTED_VALUE"""),"Aceite oliva extra virgen 5 lts") -> Aceite oliva extra virgen 5 lts | C3: 1.524 | D3: =IFERROR(__xludf.DUMMYFUNCTION("FILTER('UNIVERSO PRODUCTOS'!C1:C961, ISNUMBER(SEARCH(A1, 'UNIVERSO PRODUCTOS'!K1:K961))) "),4646.2) -> 4646.2 | E3: =IFERROR(__xludf.DUMMYFUNCTION("FILTER('UNIVERSO PRODUCTOS'!D1:D958, ISNUMBER(SEARCH(A1, 'UNIVERSO PRODUCTOS'!K1:K958))) "),"LT") -> LT | F3: =IFERROR(__xludf.DUMMYFUNCTION("FILTER('UNIVERSO PRODUCTOS'!H1:H958, ISNUMBER(SEARCH(A1, 'UNIVERSO PRODUCTOS'!K1:K958))) "),"Abarrotes") -> Abarrotes | G3: =(C3)*D3 -> 7080.8088 | H3: =G3*19% -> 1345.3537 | I3: =G3+H3 -> 8426.1625
A4: =IFERROR(__xludf.DUMMYFUNCTION("""COMPUTED_VALUE"""),"ti-ing-5a1041f6-5fed-4ae0-8d00-dee7d47968a3") -> ti-ing-5a1041f6-5fed-4ae0-8d00-dee7d47968a3 | B4: =IFERROR(__xludf.DUMMYFUNCTION("""COMPUTED_VALUE"""),"Aceite vegetal 900 ml") -> Aceite vegetal 900 ml | C4: 6 | D4: =IFERROR(__xludf.DUMMYFUNCTION("""COMPUTED_VALUE"""),1540.6) -> 1540.6 | E4: =IFERROR(__xludf.DUMMYFUNCTION("""COMPUTED_VALUE"""),"UN") -> UN | F4: =IFERROR(__xludf.DUMMYFUNCTION("""COMPUTED_VALUE"""),"Abarrotes") -> Abarrotes | G4: =(C4)*D4 -> 9243.6 | H4: =G4*19% -> 1756.284 | I4: =G4+H4 -> 10999.884 | L4: Abarrotes | M4: Aseo | N4: Bebestibles | O4: Cafetería | P4: Carnes y Aves | Q4: Desechables | R4: Frutas y Verduras | S4: Harinas | T4: Ovolacteos | U4: Pastelería | V4: Pescados y Mariscos | W4: P.Terminados | X4: Té | Y4: Valor Neto
A5: =IFERROR(__xludf.DUMMYFUNCTION("""COMPUTED_VALUE"""),"ti-ing-0ab486df-7d4d-4782-82bb-c30b4209e5fb") -> ti-ing-0ab486df-7d4d-4782-82bb-c30b4209e5fb | B5: =IFERROR(__xludf.DUMMYFUNCTION("""COMPUTED_VALUE"""),"Aceituna Morada kg") -> Aceituna Morada kg | C5: 1.278 | D5: =IFERROR(__xludf.DUMMYFUNCTION("""COMPUTED_VALUE"""),7130) -> 7130 | E5: =IFERROR(__xludf.DUMMYFUNCTION("""COMPUTED_VALUE"""),"KG") -> KG | F5: =IFERROR(__xludf.DUMMYFUNCTION("""COMPUTED_VALUE"""),"Abarrotes") -> Abarrotes | G5: =(C5)*D5 -> 9112.14 | H5: =G5*19% -> 1731.3066 | I5: =G5+H5 -> 10843.447
A6: =IFERROR(__xludf.DUMMYFUNCTION("""COMPUTED_VALUE"""),"ti-ing-581e5046-d41b-44fd-981a-fa5ec2c4d4ba") -> ti-ing-581e5046-d41b-44fd-981a-fa5ec2c4d4ba | B6: =IFERROR(__xludf.DUMMYFUNCTION("""COMPUTED_VALUE"""),"Ajinomoto") -> Ajinomoto | C6: 0.476 | D6: =IFERROR(__xludf.DUMMYFUNCTION("""COMPUTED_VALUE"""),3354) -> 3354 | E6: =IFERROR(__xludf.DUMMYFUNCTION("""COMPUTED_VALUE"""),"kg") -> kg | F6: =IFERROR(__xludf.DUMMYFUNCTION("""COMPUTED_VALUE"""),"Abarrotes") -> Abarrotes | G6: =(C6)*D6 -> 1596.504 | H6: =G6*19% -> 303.33576 | I6: =G6+H6 -> 1899.8398 | L6: =SUM(G3:G45) -> 145971.49 | M6: =SUM(G46:G63) -> 64394.913 | P6: =SUM(G64:G76) -> 319553.82 | Q6: =SUM(G77:G85) -> 42169.185 | R6: =SUM(G86:G120) -> 177430.72 | S6: =SUM(G121) -> 7156.3331 | T6: =SUM(G122:G131) -> 145824.48 | V6: =SUM(G132:G133) -> 0 | W6: =SUM(G134:G175) -> 487668.19 | Y6: =SUM(L6:X6) -> 1390169.1
A7: =IFERROR(__xludf.DUMMYFUNCTION("""COMPUTED_VALUE"""),"ti-ing-bfd5d10e-d265-4e6e-b05a-79c836269380") -> ti-ing-bfd5d10e-d265-4e6e-b05a-79c836269380 | B7: =IFERROR(__xludf.DUMMYFUNCTION("""COMPUTED_VALUE"""),"Arroz (colacion)") -> Arroz (colacion) | C7: 0 | D7: =IFERROR(__xludf.DUMMYFUNCTION("""COMPUTED_VALUE"""),905) -> 905 | E7: =IFERROR(__xludf.DUMMYFUNCTION("""COMPUTED_VALUE"""),"KG") -> KG | F7: =IFERROR(__xludf.DUMMYFUNCTION("""COMPUTED_VALUE"""),"Abarrotes") -> Abarrotes | G7: =(C7)*D7 -> 0 | H7: =G7*19% -> 0 | I7: =G7+H7 -> 0
A8: =IFERROR(__xludf.DUMMYFUNCTION("""COMPUTED_VALUE"""),"ti-ing-5c316419-1759-4d90-bb2e-e9025a87d122") -> ti-ing-5c316419-1759-4d90-bb2e-e9025a87d122 | B8: =IFERROR(__xludf.DUMMYFUNCTION("""COMPUTED_VALUE"""),"Atun Coliseo Al Agua") -> Atun Coliseo Al Agua | C8: 0 | D8: =IFERROR(__xludf.DUMMYFUNCTION("""COMPUTED_VALUE"""),879) -> 879 | E8: =IFERROR(__xludf.DUMMYFUNCTION("""COMPUTED_VALUE"""),"UN") -> UN | F8: =IFERROR(__xludf.DUMMYFUNCTION("""COMPUTED_VALUE"""),"Abarrotes") -> Abarrotes | G8: =(C8)*D8 -> 0 | H8: =G8*19% -> 0 | I8: =G8+H8 -> 0 | L8: Abarrotes | M8: Aseo | N8: Bebestibles | O8: Cafetería | P8: Carnes y Aves | Q8: Desechables | R8: Frutas y Verduras | S8: Harinas | T8: Ovolacteos | U8: Pastelería | V8: Pescados y Mariscos | W8: P.Terminados | X8: Té | Y8: Valor Bruto
A9: =IFERROR(__xludf.DUMMYFUNCTION("""COMPUTED_VALUE"""),"ti-ing-363a5ec1-8d6b-4612-be6a-7a19b61ab7e2") -> ti-ing-363a5ec1-8d6b-4612-be6a-7a19b61ab7e2 | B9: =IFERROR(__xludf.DUMMYFUNCTION("""COMPUTED_VALUE"""),"Atun Dorasol Al Agua") -> Atun Dorasol Al Agua | C9: 0 | D9: =IFERROR(__xludf.DUMMYFUNCTION("""COMPUTED_VALUE"""),879) -> 879 | E9: =IFERROR(__xludf.DUMMYFUNCTION("""COMPUTED_VALUE"""),"UN") -> UN | F9: =IFERROR(__xludf.DUMMYFUNCTION("""COMPUTED_VALUE"""),"Abarrotes") -> Abarrotes | G9: =(C9)*D9 -> 0 | H9: =G9*19% -> 0 | I9: =G9+H9 -> 0
A10: =IFERROR(__xludf.DUMMYFUNCTION("""COMPUTED_VALUE"""),"ti-ing-531d1d9b-814d-49bc-9bbf-06be4ae2e6d5") -> ti-ing-531d1d9b-814d-49bc-9bbf-06be4ae2e6d5 | B10: =IFERROR(__xludf.DUMMYFUNCTION("""COMPUTED_VALUE"""),"Azucar blanca") -> Azucar blanca | C10: 1.264 | D10: =IFERROR(__xludf.DUMMYFUNCTION("""COMPUTED_VALUE"""),939.9985) -> 939.9985 | E10: =IFERROR(__xludf.DUMMYFUNCTION("""COMPUTED_VALUE"""),"KG") -> KG | F10: =IFERROR(__xludf.DUMMYFUNCTION("""COMPUTED_VALUE"""),"Abarrotes") -> Abarrotes | G10: =(C10)*D10 -> 1188.1581 | H10: =G10*19% -> 225.75004 | I10: =G10+H10 -> 1413.9081 | L10: =SUM(I3:I45) -> 173706.08 | M10: =SUM(I46:I63) -> 76629.947 | P10: =SUM(I64:I76) -> 380269.05 | Q10: =SUM(I77:I85) -> 50181.331 | R10: =SUM(I86:I120) -> 211142.56 | S10: =SUM(I121) -> 8516.0364 | T10: =SUM(I122:I131) -> 173531.13 | V10: =SUM(I132:I133) -> 0 | W10: =SUM(I134:I175) -> 580325.14 | Y10: =SUM(L10:X10) -> 1654301.3
B11: =IFERROR(__xludf.DUMMYFUNCTION("""COMPUTED_VALUE"""),"Azúcar blanca por kilo") -> Azúcar blanca por kilo | C11: 0 | D11: =IFERROR(__xludf.DUMMYFUNCTION("""COMPUTED_VALUE"""),930) -> 930 | E11: =IFERROR(__xludf.DUMMYFUNCTION("""COMPUTED_VALUE"""),"KG") -> KG | F11: =IFERROR(__xludf.DUMMYFUNCTION("""COMPUTED_VALUE"""),"Abarrotes") -> Abarrotes | G11: =(C11)*D11 -> 0 | H11: =G11*19% -> 0 | I11: =G11+H11 -> 0
A12: =IFERROR(__xludf.DUMMYFUNCTION("""COMPUTED_VALUE"""),"ti-ing-c4486ce7-85c4-49c5-ac82-4d98b0798d01") -> ti-ing-c4486ce7-85c4-49c5-ac82-4d98b0798d01 | B12: =IFERROR(__xludf.DUMMYFUNCTION("""COMPUTED_VALUE"""),"Azucar rubia") -> Azucar rubia | C12: 0.75 | D12: =IFERROR(__xludf.DUMMYFUNCTION("""COMPUTED_VALUE"""),1047) -> 1047 | E12: =IFERROR(__xludf.DUMMYFUNCTION("""COMPUTED_VALUE"""),"KG") -> KG | F12: =IFERROR(__xludf.DUMMYFUNCTION("""COMPUTED_VALUE"""),"Abarrotes") -> Abarrotes | G12: =(C12)*D12 -> 785.25 | H12: =G12*19% -> 149.1975 | I12: =G12+H12 -> 934.4475
A13: =IFERROR(__xludf.DUMMYFUNCTION("""COMPUTED_VALUE"""),"ti-ing-63a7f9f9-77ff-45f4-9e3f-3feff0b73432") -> ti-ing-63a7f9f9-77ff-45f4-9e3f-3feff0b73432 | B13: =IFERROR(__xludf.DUMMYFUNCTION("""COMPUTED_VALUE"""),"Café tarro grande (desayuno)") -> Café tarro grande (desayuno) | C13: 0.5 | D13: =IFERROR(__xludf.DUMMYFUNCTION("""COMPUTED_VALUE"""),12032) -> 12032 | E13: =IFERROR(__xludf.DUMMYFUNCTION("""COMPUTED_VALUE"""),"UN") -> UN | F13: =IFERROR(__xludf.DUMMYFUNCTION("""COMPUTED_VALUE"""),"Abarrotes") -> Abarrotes | G13: =(C13)*D13 -> 6016 | H13: =G13*19% -> 1143.04 | I13: =G13+H13 -> 7159.04
A14: =IFERROR(__xludf.DUMMYFUNCTION("""COMPUTED_VALUE"""),"ti-ing-280562df-e2c6-469c-bfaf-8f7361fb5c74") -> ti-ing-280562df-e2c6-469c-bfaf-8f7361fb5c74 | B14: =IFERROR(__xludf.DUMMYFUNCTION("""COMPUTED_VALUE"""),"COMINO") -> COMINO | C14: 0.414 | D14: =IFERROR(__xludf.DUMMYFUNCTION("""COMPUTED_VALUE"""),5250) -> 5250 | E14: =IFERROR(__xludf.DUMMYFUNCTION("""COMPUTED_VALUE"""),"KG") -> KG | F14: =IFERROR(__xludf.DUMMYFUNCTION("""COMPUTED_VALUE"""),"Abarrotes") -> Abarrotes | G14: =(C14)*D14 -> 2173.5 | H14: =G14*19% -> 412.965 | I14: =G14+H14 -> 2586.465
A15: =IFERROR(__xludf.DUMMYFUNCTION("""COMPUTED_VALUE"""),"ti-ing-55e22a4e-70ba-4bfe-9ef6-78d09a6c71b6") -> ti-ing-55e22a4e-70ba-4bfe-9ef6-78d09a6c71b6 | B15: =IFERROR(__xludf.DUMMYFUNCTION("""COMPUTED_VALUE"""),"Curcuma") -> Curcuma | C15: 0.284 | D15: =IFERROR(__xludf.DUMMYFUNCTION("""COMPUTED_VALUE"""),5437) -> 5437 | E15: =IFERROR(__xludf.DUMMYFUNCTION("""COMPUTED_VALUE"""),"KG") -> KG | F15: =IFERROR(__xludf.DUMMYFUNCTION("""COMPUTED_VALUE"""),"Abarrotes") -> Abarrotes | G15: =(C15)*D15 -> 1544.108 | H15: =G15*19% -> 293.38052 | I15: =G15+H15 -> 1837.4885
A16: =IFERROR(__xludf.DUMMYFUNCTION("""COMPUTED_VALUE"""),"ti-ing-2fbc1c56-3286-4d64-8ddd-b547296361a3") -> ti-ing-2fbc1c56-3286-4d64-8ddd-b547296361a3 | B16: =IFERROR(__xludf.DUMMYFUNCTION("""COMPUTED_VALUE"""),"Espaguetti") -> Espaguetti | C16: 0 | D16: =IFERROR(__xludf.DUMMYFUNCTION("""COMPUTED_VALUE"""),407) -> 407 | E16: =IFERROR(__xludf.DUMMYFUNCTION("""COMPUTED_VALUE"""),"UN") -> UN | F16: =IFERROR(__xludf.DUMMYFUNCTION("""COMPUTED_VALUE"""),"Abarrotes") -> Abarrotes | G16: =(C16)*D16 -> 0 | H16: =G16*19% -> 0 | I16: =G16+H16 -> 0
A17: =IFERROR(__xludf.DUMMYFUNCTION("""COMPUTED_VALUE"""),"ti-ing-446530ff-42dc-41f9-9208-1b6c8dded86f") -> ti-ing-446530ff-42dc-41f9-9208-1b6c8dded86f | B17: =IFERROR(__xludf.DUMMYFUNCTION("""COMPUTED_VALUE"""),"Espirales") -> Espirales | C17: 0 | D17: =IFERROR(__xludf.DUMMYFUNCTION("""COMPUTED_VALUE"""),399) -> 399 | E17: =IFERROR(__xludf.DUMMYFUNCTION("""COMPUTED_VALUE"""),"UN") -> UN | F17: =IFERROR(__xludf.DUMMYFUNCTION("""COMPUTED_VALUE"""),"Abarrotes") -> Abarrotes | G17: =(C17)*D17 -> 0 | H17: =G17*19% -> 0 | I17: =G17+H17 -> 0
A18: =IFERROR(__xludf.DUMMYFUNCTION("""COMPUTED_VALUE"""),"ti-ing-11a33780-09cc-47f7-b11c-89e4b6139bb9") -> ti-ing-11a33780-09cc-47f7-b11c-89e4b6139bb9 | B18: =IFERROR(__xludf.DUMMYFUNCTION("""COMPUTED_VALUE"""),"Garbanzos") -> Garbanzos | C18: 0 | D18: =IFERROR(__xludf.DUMMYFUNCTION("""COMPUTED_VALUE"""),2291.25) -> 2291.25 | E18: =IFERROR(__xludf.DUMMYFUNCTION("""COMPUTED_VALUE"""),"KG") -> KG | F18: =IFERROR(__xludf.DUMMYFUNCTION("""COMPUTED_VALUE"""),"Abarrotes") -> Abarrotes | G18: =(C18)*D18 -> 0 | H18: =G18*19% -> 0 | I18: =G18+H18 -> 0
A19: =IFERROR(__xludf.DUMMYFUNCTION("""COMPUTED_VALUE"""),"ti-ing-16366b6f-c022-48bc-9b77-61765f107986") -> ti-ing-16366b6f-c022-48bc-9b77-61765f107986 | B19: =IFERROR(__xludf.DUMMYFUNCTION("""COMPUTED_VALUE"""),"Harina pan") -> Harina pan | C19: 0 | D19: =IFERROR(__xludf.DUMMYFUNCTION("""COMPUTED_VALUE"""),1638.667) -> 1638.667 | E19: =IFERROR(__xludf.DUMMYFUNCTION("""COMPUTED_VALUE"""),"KG") -> KG | F19: =IFERROR(__xludf.DUMMYFUNCTION("""COMPUTED_VALUE"""),"Abarrotes") -> Abarrotes | G19: =(C19)*D19 -> 0 | H19: =G19*19% -> 0 | I19: =G19+H19 -> 0
A20: =IFERROR(__xludf.DUMMYFUNCTION("""COMPUTED_VALUE"""),"ti-ing-e6ff2cd2-0729-44b9-b0d3-457299c1ead8") -> ti-ing-e6ff2cd2-0729-44b9-b0d3-457299c1ead8 | B20: =IFERROR(__xludf.DUMMYFUNCTION("""COMPUTED_VALUE"""),"Huevos Arizona") -> Huevos Arizona | C20: 177 | D20: =IFERROR(__xludf.DUMMYFUNCTION("""COMPUTED_VALUE"""),138) -> 138 | E20: =IFERROR(__xludf.DUMMYFUNCTION("""COMPUTED_VALUE"""),"UN") -> UN | F20: =IFERROR(__xludf.DUMMYFUNCTION("""COMPUTED_VALUE"""),"Abarrotes") -> Abarrotes | G20: =(C20)*D20 -> 24426 | H20: =G20*19% -> 4640.94 | I20: =G20+H20 -> 29066.94
A21: =IFERROR(__xludf.DUMMYFUNCTION("""COMPUTED_VALUE"""),"ti-ing-06898fd0-9448-431b-9bad-3526a93cf181") -> ti-ing-06898fd0-9448-431b-9bad-3526a93cf181 | B21: =IFERROR(__xludf.DUMMYFUNCTION("""COMPUTED_VALUE"""),"Ketchup kg") -> Ketchup kg | C21: 0 | D21: =IFERROR(__xludf.DUMMYFUNCTION("""COMPUTED_VALUE"""),1550) -> 1550 | E21: =IFERROR(__xludf.DUMMYFUNCTION("""COMPUTED_VALUE"""),"KG") -> KG | F21: =IFERROR(__xludf.DUMMYFUNCTION("""COMPUTED_VALUE"""),"Abarrotes") -> Abarrotes | G21: =(C21)*D21 -> 0 | H21: =G21*19% -> 0 | I21: =G21+H21 -> 0
A22: =IFERROR(__xludf.DUMMYFUNCTION("""COMPUTED_VALUE"""),"ti-ing-f3eeca8c-b308-4136-a438-0f68fc53c279") -> ti-ing-f3eeca8c-b308-4136-a438-0f68fc53c279 | B22: =IFERROR(__xludf.DUMMYFUNCTION("""COMPUTED_VALUE"""),"Lasagne Chef") -> Lasagne Chef | C22: 2.44 | D22: =IFERROR(__xludf.DUMMYFUNCTION("""COMPUTED_VALUE"""),3831.8) -> 3831.8 | E22: =IFERROR(__xludf.DUMMYFUNCTION("""COMPUTED_VALUE"""),"kg") -> kg | F22: =IFERROR(__xludf.DUMMYFUNCTION("""COMPUTED_VALUE"""),"Abarrotes") -> Abarrotes | G22: =(C22)*D22 -> 9349.592 | H22: =G22*19% -> 1776.4225 | I22: =G22+H22 -> 11126.014
A23: =IFERROR(__xludf.DUMMYFUNCTION("""COMPUTED_VALUE"""),"ti-ing-20a9682d-4a6c-42c4-a3ed-312cab8df904") -> ti-ing-20a9682d-4a6c-42c4-a3ed-312cab8df904 | B23: =IFERROR(__xludf.DUMMYFUNCTION("""COMPUTED_VALUE"""),"Laurel") -> Laurel | C23: 0.118 | D23: =IFERROR(__xludf.DUMMYFUNCTION("""COMPUTED_VALUE"""),75280) -> 75280 | E23: =IFERROR(__xludf.DUMMYFUNCTION("""COMPUTED_VALUE"""),"KG") -> KG | F23: =IFERROR(__xludf.DUMMYFUNCTION("""COMPUTED_VALUE"""),"Abarrotes") -> Abarrotes | G23: =(C23)*D23 -> 8883.04 | H23: =G23*19% -> 1687.7776 | I23: =G23+H23 -> 10570.818
A24: =IFERROR(__xludf.DUMMYFUNCTION("""COMPUTED_VALUE"""),"ti-ing-a5f32751-2fe1-4388-acd1-977dd4d921a6") -> ti-ing-a5f32751-2fe1-4388-acd1-977dd4d921a6 | B24: =IFERROR(__xludf.DUMMYFUNCTION("""COMPUTED_VALUE"""),"Lentejas (colacion personal)") -> Lentejas (colacion personal) | C24: 0 | D24: =IFERROR(__xludf.DUMMYFUNCTION("""COMPUTED_VALUE"""),2118) -> 2118 | E24: =IFERROR(__xludf.DUMMYFUNCTION("""COMPUTED_VALUE"""),"KG") -> KG | F24: =IFERROR(__xludf.DUMMYFUNCTION("""COMPUTED_VALUE"""),"Abarrotes") -> Abarrotes | G24: =(C24)*D24 -> 0 | H24: =G24*19% -> 0 | I24: =G24+H24 -> 0
A25: =IFERROR(__xludf.DUMMYFUNCTION("""COMPUTED_VALUE"""),"ti-ing-69061f8d-e4d9-4fc4-b44e-0cd173ebf8f3") -> ti-ing-69061f8d-e4d9-4fc4-b44e-0cd173ebf8f3 | B25: =IFERROR(__xludf.DUMMYFUNCTION("""COMPUTED_VALUE"""),"Maicena kg") -> Maicena kg | C25: 0.648 | D25: =IFERROR(__xludf.DUMMYFUNCTION("""COMPUTED_VALUE"""),1582) -> 1582 | E25: =IFERROR(__xludf.DUMMYFUNCTION("""COMPUTED_VALUE"""),"KG") -> KG | F25: =IFERROR(__xludf.DUMMYFUNCTION("""COMPUTED_VALUE"""),"Abarrotes") -> Abarrotes | G25: =(C25)*D25 -> 1025.136 | H25: =G25*19% -> 194.77584 | I25: =G25+H25 -> 1219.9118
A26: =IFERROR(__xludf.DUMMYFUNCTION("""COMPUTED_VALUE"""),"ti-ing-3dba6697-1589-49e0-8e6e-951b48b7d160") -> ti-ing-3dba6697-1589-49e0-8e6e-951b48b7d160 | B26: =IFERROR(__xludf.DUMMYFUNCTION("""COMPUTED_VALUE"""),"Mayonesa Hellmans") -> Mayonesa Hellmans | C26: 5.918 | D26: =IFERROR(__xludf.DUMMYFUNCTION("""COMPUTED_VALUE"""),3989.362) -> 3989.362 | E26: =IFERROR(__xludf.DUMMYFUNCTION("""COMPUTED_VALUE"""),"Kg") -> Kg | F26: =IFERROR(__xludf.DUMMYFUNCTION("""COMPUTED_VALUE"""),"Abarrotes") -> Abarrotes | G26: =(C26)*D26 -> 23609.044 | H26: =G26*19% -> 4485.7184 | I26: =G26+H26 -> 28094.763
B27: =IFERROR(__xludf.DUMMYFUNCTION("""COMPUTED_VALUE"""),"Metabisulfito de sodio") -> Metabisulfito de sodio | C27: 0.114 | D27: =IFERROR(__xludf.DUMMYFUNCTION("""COMPUTED_VALUE"""),14958) -> 14958 | E27: =IFERROR(__xludf.DUMMYFUNCTION("""COMPUTED_VALUE"""),"KG") -> KG | F27: =IFERROR(__xludf.DUMMYFUNCTION("""COMPUTED_VALUE"""),"Abarrotes") -> Abarrotes | G27: =(C27)*D27 -> 1705.212 | H27: =G27*19% -> 323.99028 | I27: =G27+H27 -> 2029.2023
A28: =IFERROR(__xludf.DUMMYFUNCTION("""COMPUTED_VALUE"""),"ti-ing-55acf21a-55c1-406f-a76b-b81347750e20") -> ti-ing-55acf21a-55c1-406f-a76b-b81347750e20 | B28: =IFERROR(__xludf.DUMMYFUNCTION("""COMPUTED_VALUE"""),"Mostaza") -> Mostaza | C28: 1.246 | D28: =IFERROR(__xludf.DUMMYFUNCTION("""COMPUTED_VALUE"""),1336) -> 1336 | E28: =IFERROR(__xludf.DUMMYFUNCTION("""COMPUTED_VALUE"""),"KG") -> KG | F28: =IFERROR(__xludf.DUMMYFUNCTION("""COMPUTED_VALUE"""),"Abarrotes") -> Abarrotes | G28: =(C28)*D28 -> 1664.656 | H28: =G28*19% -> 316.28464 | I28: =G28+H28 -> 1980.9406
A29: =IFERROR(__xludf.DUMMYFUNCTION("""COMPUTED_VALUE"""),"ti-ing-1a1ad4e7-e7d7-4d58-a706-bfd83210f90b") -> ti-ing-1a1ad4e7-e7d7-4d58-a706-bfd83210f90b | B29: =IFERROR(__xludf.DUMMYFUNCTION("""COMPUTED_VALUE"""),"Oregano kg") -> Oregano kg | C29: 0.902 | D29: =IFERROR(__xludf.DUMMYFUNCTION("""COMPUTED_VALUE"""),4812) -> 4812 | E29: =IFERROR(__xludf.DUMMYFUNCTION("""COMPUTED_VALUE"""),"KG") -> KG | F29: =IFERROR(__xludf.DUMMYFUNCTION("""COMPUTED_VALUE"""),"Abarrotes") -> Abarrotes | G29: =(C29)*D29 -> 4340.424 | H29: =G29*19% -> 824.68056 | I29: =G29+H29 -> 5165.1046
A30: =IFERROR(__xludf.DUMMYFUNCTION("""COMPUTED_VALUE"""),"ti-ing-dc13f521-8e90-4186-98aa-e2a49341278b") -> ti-ing-dc13f521-8e90-4186-98aa-e2a49341278b | B30: =IFERROR(__xludf.DUMMYFUNCTION("""COMPUTED_VALUE"""),"Paprika") -> Paprika | C30: 0.822 | D30: =IFERROR(__xludf.DUMMYFUNCTION("""COMPUTED_VALUE"""),3850) -> 3850 | E30: =IFERROR(__xludf.DUMMYFUNCTION("""COMPUTED_VALUE"""),"KG") -> KG | F30: =IFERROR(__xludf.DUMMYFUNCTION("""COMPUTED_VALUE"""),"Abarrotes") -> Abarrotes | G30: =(C30)*D30 -> 3164.7 | H30: =G30*19% -> 601.293 | I30: =G30+H30 -> 3765.993
B31: =IFERROR(__xludf.DUMMYFUNCTION("""COMPUTED_VALUE"""),"Pasta aji panca") -> Pasta aji panca | C31: 0 | D31: =IFERROR(__xludf.DUMMYFUNCTION("""COMPUTED_VALUE"""),14335) -> 14335 | E31: =IFERROR(__xludf.DUMMYFUNCTION("""COMPUTED_VALUE"""),"KG") -> KG | F31: =IFERROR(__xludf.DUMMYFUNCTION("""COMPUTED_VALUE"""),"Abarrotes") -> Abarrotes | G31: =(C31)*D31 -> 0 | H31: =G31*19% -> 0 | I31: =G31+H31 -> 0
A32: =IFERROR(__xludf.DUMMYFUNCTION("""COMPUTED_VALUE"""),"ti-ing-dce3151a-440e-4adc-b6f6-75fb61de8ac6") -> ti-ing-dce3151a-440e-4adc-b6f6-75fb61de8ac6 | B32: =IFERROR(__xludf.DUMMYFUNCTION("""COMPUTED_VALUE"""),"Pimienta") -> Pimienta | C32: 0.224 | D32: =IFERROR(__xludf.DUMMYFUNCTION("""COMPUTED_VALUE"""),11258) -> 11258 | E32: =IFERROR(__xludf.DUMMYFUNCTION("""COMPUTED_VALUE"""),"UN") -> UN | F32: =IFERROR(__xludf.DUMMYFUNCTION("""COMPUTED_VALUE"""),"Abarrotes") -> Abarrotes | G32: =(C32)*D32 -> 2521.792 | H32: =G32*19% -> 479.14048 | I32: =G32+H32 -> 3000.9325
A33: =IFERROR(__xludf.DUMMYFUNCTION("""COMPUTED_VALUE"""),"ti-ing-904468d1-7aa3-4ea8-a76b-bb2fb6b316e2") -> ti-ing-904468d1-7aa3-4ea8-a76b-bb2fb6b316e2 | B33: =IFERROR(__xludf.DUMMYFUNCTION("""COMPUTED_VALUE"""),"Porotos") -> Porotos | C33: 0 | D33: =IFERROR(__xludf.DUMMYFUNCTION("""COMPUTED_VALUE"""),1778) -> 1778 | E33: =IFERROR(__xludf.DUMMYFUNCTION("""COMPUTED_VALUE"""),"KG") -> KG | F33: =IFERROR(__xludf.DUMMYFUNCTION("""COMPUTED_VALUE"""),"Abarrotes") -> Abarrotes | G33: =(C33)*D33 -> 0 | H33: =G33*19% -> 0 | I33: =G33+H33 -> 0
A34: =IFERROR(__xludf.DUMMYFUNCTION("""COMPUTED_VALUE"""),"ti-ing-67451d2d-c408-4de8-b583-b73d147b0c3c") -> ti-ing-67451d2d-c408-4de8-b583-b73d147b0c3c | B34: =IFERROR(__xludf.DUMMYFUNCTION("""COMPUTED_VALUE"""),"Porotos verde") -> Porotos verde | C34: 0 | D34: =IFERROR(__xludf.DUMMYFUNCTION("""COMPUTED_VALUE"""),680) -> 680 | E34: =IFERROR(__xludf.DUMMYFUNCTION("""COMPUTED_VALUE"""),"KG") -> KG | F34: =IFERROR(__xludf.DUMMYFUNCTION("""COMPUTED_VALUE"""),"Abarrotes") -> Abarrotes | G34: =(C34)*D34 -> 0 | H34: =G34*19% -> 0 | I34: =G34+H34 -> 0
B35: =IFERROR(__xludf.DUMMYFUNCTION("""COMPUTED_VALUE"""),"Quinua mixta") -> Quinua mixta | C35: 0.616 | D35: =IFERROR(__xludf.DUMMYFUNCTION("""COMPUTED_VALUE"""),4596) -> 4596 | E35: =IFERROR(__xludf.DUMMYFUNCTION("""COMPUTED_VALUE"""),"KG") -> KG | F35: =IFERROR(__xludf.DUMMYFUNCTION("""COMPUTED_VALUE"""),"Abarrotes") -> Abarrotes | G35: =(C35)*D35 -> 2831.136 | H35: =G35*19% -> 537.91584 | I35: =G35+H35 -> 3369.0518
A36: =IFERROR(__xludf.DUMMYFUNCTION("""COMPUTED_VALUE"""),"ti-ing-93b9bb76-8e33-404b-b4a2-19bddccf01ff") -> ti-ing-93b9bb76-8e33-404b-b4a2-19bddccf01ff | B36: =IFERROR(__xludf.DUMMYFUNCTION("""COMPUTED_VALUE"""),"Romero") -> Romero | C36: 0.278 | D36: =IFERROR(__xludf.DUMMYFUNCTION("""COMPUTED_VALUE"""),7135.19) -> 7135.19 | E36: =IFERROR(__xludf.DUMMYFUNCTION("""COMPUTED_VALUE"""),"UN") -> UN | F36: =IFERROR(__xludf.DUMMYFUNCTION("""COMPUTED_VALUE"""),"Abarrotes") -> Abarrotes | G36: =(C36)*D36 -> 1983.5828 | H36: =G36*19% -> 376.88074 | I36: =G36+H36 -> 2360.4636
A37: =IFERROR(__xludf.DUMMYFUNCTION("""COMPUTED_VALUE"""),"ti-ing-4818468c-bc91-40f7-9fa4-eb19def3bff7") -> ti-ing-4818468c-bc91-40f7-9fa4-eb19def3bff7 | B37: =IFERROR(__xludf.DUMMYFUNCTION("""COMPUTED_VALUE"""),"Sal fina") -> Sal fina | C37: 0.502 | D37: =IFERROR(__xludf.DUMMYFUNCTION("""COMPUTED_VALUE"""),290) -> 290 | E37: =IFERROR(__xludf.DUMMYFUNCTION("""COMPUTED_VALUE"""),"KG") -> KG | F37: =IFERROR(__xludf.DUMMYFUNCTION("""COMPUTED_VALUE"""),"Abarrotes") -> Abarrotes | G37: =(C37)*D37 -> 145.58 | H37: =G37*19% -> 27.6602 | I37: =G37+H37 -> 173.2402
A38: =IFERROR(__xludf.DUMMYFUNCTION("""COMPUTED_VALUE"""),"ti-ing-562ebc87-5bd7-439e-9451-999b88fdd759") -> ti-ing-562ebc87-5bd7-439e-9451-999b88fdd759 | B38: =IFERROR(__xludf.DUMMYFUNCTION("""COMPUTED_VALUE"""),"Salsa De Tomate") -> Salsa De Tomate | C38: 1.326 | D38: =IFERROR(__xludf.DUMMYFUNCTION("""COMPUTED_VALUE"""),1587) -> 1587 | E38: =IFERROR(__xludf.DUMMYFUNCTION("""COMPUTED_VALUE"""),"KG") -> KG | F38: =IFERROR(__xludf.DUMMYFUNCTION("""COMPUTED_VALUE"""),"Abarrotes") -> Abarrotes | G38: =(C38)*D38 -> 2104.362 | H38: =G38*19% -> 399.82878 | I38: =G38+H38 -> 2504.1908
A39: =IFERROR(__xludf.DUMMYFUNCTION("""COMPUTED_VALUE"""),"ti-ing-4f8ac25a-9411-4a59-806f-62cee4c4e0f1") -> ti-ing-4f8ac25a-9411-4a59-806f-62cee4c4e0f1 | B39: =IFERROR(__xludf.DUMMYFUNCTION("""COMPUTED_VALUE"""),"Salsa inglesa") -> Salsa inglesa | C39: 0.282 | D39: =IFERROR(__xludf.DUMMYFUNCTION("""COMPUTED_VALUE"""),4035) -> 4035 | E39: =IFERROR(__xludf.DUMMYFUNCTION("""COMPUTED_VALUE"""),"Kg") -> Kg | F39: =IFERROR(__xludf.DUMMYFUNCTION("""COMPUTED_VALUE"""),"Abarrotes") -> Abarrotes | G39: =(C39)*D39 -> 1137.87 | H39: =G39*19% -> 216.1953 | I39: =G39+H39 -> 1354.0653
A40: =IFERROR(__xludf.DUMMYFUNCTION("""COMPUTED_VALUE"""),"ti-ing-9f3dba64-3cca-408b-ac1e-45359966da75") -> ti-ing-9f3dba64-3cca-408b-ac1e-45359966da75 | B40: =IFERROR(__xludf.DUMMYFUNCTION("""COMPUTED_VALUE"""),"Salsa Soya") -> Salsa Soya | C40: 0.9 | D40: =IFERROR(__xludf.DUMMYFUNCTION("""COMPUTED_VALUE"""),1625) -> 1625 | E40: =IFERROR(__xludf.DUMMYFUNCTION("""COMPUTED_VALUE"""),"KG") -> KG | F40: =IFERROR(__xludf.DUMMYFUNCTION("""COMPUTED_VALUE"""),"Abarrotes") -> Abarrotes | G40: =(C40)*D40 -> 1462.5 | H40: =G40*19% -> 277.875 | I40: =G40+H40 -> 1740.375
...

Sheet servicio
A1: Stock Servicio | B1: Stock Servicio
A2: ID PRODUCTO | B2: PRODUCTO | C2: STOCK | D2: PEDIDO | E2: UN MEDIDA | F2: CATEGORIA | G2: Valorizado Neto | H2: IVA (19%) | I2: Total Bruto | J2: PEDIDO
